<?xml version="1.0"?>
<robot xmlns:xacro="http://www.ros.org/wiki/xacro" >
  <link name="world" />

  <joint name="world_joint" type= "fixed" >
    <parent link= "world" />
    <child link= "base_link" />
    <origin xyz="0 0 0" rpy= "0 0 0" />
    <axis xyz= "0 0 0" />
  </joint>

  <link name="base_link"/>

  <joint name="base_joint" type= "fixed" >
    <parent link= "base_link" />
    <child link= "base_footprint" />
    <origin xyz="0 0 0" rpy= "0 0 0" />
    <axis xyz= "0 0 0" />
  </joint>

 <link name="base_footprint">
    <inertial>
      <origin xyz="0 0 0" rpy="0 0 0" />
      <mass value="0.3" />
      <inertia  ixx="0.0015590274522982615" ixy="0" ixz="0" iyy="0.0009483828246419911" iyz="0" izz="0.0021418945755022067" />
    </inertial>
    <visual>
      <origin xyz="0 0 0" rpy="0 0 0" />
      <geometry>
        <mesh filename="package://vonns2_gazebo/meshes/base_footprint.STL" />
      </geometry>
      <material name="vonns_base">
        <color rgba="0.75294 0.75294 0.75294 1" />
      </material>
    </visual>
    <collision>
      <origin xyz="0 0 0" rpy="0 0 0" />
      <geometry>
        <mesh filename="package://vonns2_gazebo/meshes/base_footprint.STL" />
      </geometry>
    </collision>
  </link>

  <gazebo reference= "base_footprint">
    <material>Gazebo/Red</material>
  </gazebo>

  <link name="servo">
    <inertial>
      <origin xyz="0 0 0" rpy="0 0 0" />
      <mass value="0.1" />
      <inertia  ixx="0.00024483332592745627" ixy="0" ixz="0" iyy="0.0002604083267182112" iyz="0" izz="3.484166532953583e-05" />
    </inertial>
    <visual>
      <origin xyz="0 0 0" rpy="0 0 0" />
      <geometry>
        <mesh filename="package://vonns2_gazebo/meshes/servo.STL" />
      </geometry>
      <material name="vonns_servo">
        <color rgba="1 0 0 1" />
      </material>
    </visual>
    <collision>
      <origin xyz="0 0 0" rpy="0 0 0" />
      <geometry>
        <mesh filename="package://vonns2_gazebo/meshes/servo.STL" />
      </geometry>
    </collision>
  </link>

  <gazebo reference= "servo">
    <material>Gazebo/Gray</material>
  </gazebo>

  <joint name="servo_joint" type="continuous">
    <origin xyz="3.3815E-05 0.0007 0.0555" rpy="-1.5708 0 0" />
    <parent link="base_footprint" />
    <child link="servo" />
    <axis xyz="0 0 1" />
    <dynamics friction="0.5" damping="0.1" />
  </joint>

  <link name="laser">
    <inertial>
      <origin xyz="0 0 0" rpy="0 0 0" />
      <mass value="0.1" />
      <inertia  ixx="6.702341210496436e-05" ixy="0" ixz="0" iyy="6.702341210496436e-05" iyz="0" izz="3.904266624355316e-05" />
    </inertial>
    <visual>
      <origin xyz="0 0 0" rpy="0 0 0" />
      <geometry>
        <mesh filename="package://vonns2_gazebo/meshes/laser.STL" />
      </geometry>
      <material name="vonns_lidar">
        <color rgba="0.19608 0.19608 0.19608 1" />
      </material>
    </visual>
    <collision>
      <origin xyz="0 0 0" rpy="0 0 0" />
      <geometry>
        <mesh filename="package://vonns2_gazebo/meshes/laser.STL" />
      </geometry>
    </collision>
  </link>

  <gazebo reference= "laser">
    <material>Gazebo/Black</material>
  </gazebo>

  <joint name="laser_joint" type="fixed">
    <origin xyz="-0.0007 -0.0925 -0.0007" rpy="1.5708 0 0" />
    <parent link="servo" />
    <child link="laser" />
    <axis xyz="0 0 0" />
  </joint>
</robot>
