<?xml version="1.0" encoding="utf-8"?>
<robot name="vonns2">
  <link name="base_link" />

  <link name="base_footprint">
    <inertial>
      <origin xyz="0.00022343 0.0060502 0.015783" rpy="0 0 0" />
      <mass value="0.41158" />
      <inertia
        ixx="0.0011593" ixy="7.0565E-10" ixz="8.6497E-09"
        iyy="0.00018314" iyz="-2.7846E-08"
        izz="0.0012467" />
    </inertial>
    <visual>
      <origin xyz="0 0 0" rpy="0 0 0" />
      <geometry>
        <mesh filename="package://vonns2/meshes/base_footprint.STL" />
      </geometry>
      <material name="">
        <color rgba="0.75294 0.75294 0.75294 1" />
      </material>
    </visual>
    <collision>
      <origin xyz="0 0 0" rpy="0 0 0" />
      <geometry>
        <mesh filename="package://vonns2/meshes/base_footprint.STL" />
      </geometry>
    </collision>
  </link>

  <joint name="base_joint" type="fixed">
    <parent link="base_link"/>
    <child link="base_footprint"/>
    <origin xyz= "0 0 0"/>
  </joint>

  <link name="laser">
    <inertial>
      <origin xyz="-8.0586E-05 0.0014083 0.044488" rpy="0 0 0" />
      <mass value="0.21463" />
      <inertia
        ixx="0.0001344" ixy="-3.5979E-11" ixz="3.4132E-07"
        iyy="0.00010228" iyz="4.9097E-08"
        izz="0.00012048" />
    </inertial>
    <visual>
      <origin xyz="0 0 0" rpy="0 0 0" />
      <geometry>
        <mesh filename="package://vonns2/meshes/laser.STL" />
      </geometry>
      <material name="">
        <color rgba="0.75294 0.75294 0.75294 1" />
      </material>
    </visual>
    <collision>
      <origin xyz="0 0 0" rpy="0 0 0" />
      <geometry>
        <mesh filename="package://vonns2/meshes/laser.STL" />
      </geometry>
    </collision>
  </link>

  <joint name="laser_joint" type="revolute">
    <origin xyz="0.00023271 -0.0014021 0.05" rpy="0 0 0" />
    <parent link="base_footprint" />
    <child link="laser" />
    <axis xyz="0 1 0" />
    <limit
      lower="-1.5708"
      upper="1.5708"
      effort="0"
      velocity="0" />
  </joint>
</robot>